Workbook
Name DadosExternos_1: 'GerDiaria (2)'!$A$1:$D$500
Name SegmentaçãodeDados_Usina: #N/A

Sheet Metas
A1: UFV | B1: 45658 | C1: 45689 | D1: 45717 | E1: 45748 | F1: 45778 | G1: 45809 | H1: 45839 | I1: 45870 | J1: 45901 | K1: 45931 | L1: 45962 | M1: 45992 | N1: 46023 | O1: 46054 | P1: 46082 | Q1: 46113 | R1: 46143 | S1: 46174 | T1: 46204 | U1: 46235 | V1: 46266 | W1: 46296 | X1: 46327 | Y1: 46357 | Z1: 46388 | AA1: 46419 | AB1: 46447 | AC1: 46478 | AD1: 46508 | AE1: 46539 | AF1: 46569 | AG1: 46600 | AH1: 46631 | AI1: 46661 | AJ1: 46692 | AK1: 46722 | AL1: 46753 | AM1: 46784 | AN1: 46813 | AO1: 46844 | AP1: 46874 | AQ1: 46905 | AR1: 46935 | AS1: 46966 | AT1: 46997 | AU1: 47027 | AV1: 47058 | AW1: 47088 | AX1: 47119 | AY1: 47150 | AZ1: 47178 | BA1: 47209 | BB1: 47239 | BC1: 47270 | BD1: 47300 | BE1: 47331 | BF1: 47362 | BG1: 47392 | BH1: 47423 | BI1: 47453 | BJ1: 47484 | BK1: 47515 | BL1: 47543 | BM1: 47574 | BN1: 47604 | BO1: 47635 | BP1: 47665 | BQ1: 47696 | BR1: 47727 | BS1: 47757 | BT1: 47788 | BU1: 47818 | BV1: 47849 | BW1: 47880 | BX1: 47908 | BY1: 47939 | BZ1: 47969 | CA1: 48000 | CB1: 48030 | CC1: 48061 | CD1: 48092 | CE1: 48122 | CF1: 48153 | CG1: 48183 | CH1: 48214 | CI1: 48245 | CJ1: 48274 | CK1: 48305 | CL1: 48335 | CM1: 48366 | CN1: 48396 | CO1: 48427 | CP1: 48458 | CQ1: 48488 | CR1: 48519 | CS1: 48549 | CT1: 48580 | CU1: 48611 | CV1: 48639 | CW1: 48670 | CX1: 48700 | CY1: 48731 | CZ1: 48761 | DA1: 48792 | DB1: 48823 | DC1: 48853 | DD1: 48884 | DE1: 48914 | DF1: 48945 | DG1: 48976 | DH1: 49004 | DI1: 49035 | DJ1: 49065 | DK1: 49096 | DL1: 49126 | DM1: 49157 | DN1: 49188 | DO1: 49218 | DP1: 49249 | DQ1: 49279 | DR1: 49310 | DS1: 49341 | DT1: 49369 | DU1: 49400 | DV1: 49430 | DW1: 49461 | DX1: 49491 | DY1: 49522 | DZ1: 49553 | EA1: 49583 | EB1: 49614 | EC1: 49644 | ED1: 49675 | EE1: 49706 | EF1: 49735 | EG1: 49766 | EH1: 49796 | EI1: 49827 | EJ1: 49857 | EK1: 49888 | EL1: 49919 | EM1: 49949 | EN1: 49980 | EO1: 50010 | EP1: 50041 | EQ1: 50072 | ER1: 50100 | ES1: 50131 | ET1: 50161 | EU1: 50192 | EV1: 50222 | EW1: 50253 | EX1: 50284 | EY1: 50314 | EZ1: 50345 | FA1: 50375 | FB1: 50406 | FC1: 50437 | FD1: 50465 | FE1: 50496 | FF1: 50526 | FG1: 50557 | FH1: 50587 | FI1: 50618 | FJ1: 50649 | FK1: 50679 | FL1: 50710 | FM1: 50740 | FN1: 50771 | FO1: 50802 | FP1: 50830 | FQ1: 50861 | FR1: 50891 | FS1: 50922 | FT1: 50952 | FU1: 50983 | FV1: 51014 | FW1: 51044 | FX1: 51075 | FY1: 51105 | FZ1: 51136 | GA1: 51167 | GB1: 51196 | GC1: 51227 | GD1: 51257 | GE1: 51288 | GF1: 51318 | GG1: 51349 | GH1: 51380 | GI1: 51410 | GJ1: 51441 | GK1: 51471 | GL1: 51502 | GM1: 51533 | GN1: 51561 | GO1: 51592 | GP1: 51622 | GQ1: 51653 | GR1: 51683 | GS1: 51714 | GT1: 51745 | GU1: 51775 | GV1: 51806 | GW1: 51836 | GX1: 51867 | GY1: 51898 | GZ1: 51926 | HA1: 51957 | HB1: 51987 | HC1: 52018 | HD1: 52048 | HE1: 52079 | HF1: 52110 | HG1: 52140 | HH1: 52171 | HI1: 52201 | HJ1: 52232 | HK1: 52263 | HL1: 52291 | HM1: 52322 | HN1: 52352 | HO1: 52383 | HP1: 52413 | HQ1: 52444 | HR1: 52475 | HS1: 52505 | HT1: 52536 | HU1: 52566 | HV1: 52597 | HW1: 52628 | HX1: 52657 | HY1: 52688 | HZ1: 52718 | IA1: 52749 | IB1: 52779 | IC1: 52810 | ID1: 52841 | IE1: 52871 | IF1: 52902 | IG1: 52932 | IH1: 52963 | II1: 52994 | IJ1: 53022 | IK1: 53053 | IL1: 53083 | IM1: 53114 | IN1: 53144 | IO1: 53175 | IP1: 53206 | IQ1: 53236 | IR1: 53267 | IS1: 53297 | IT1: 53328 | IU1: 53359 | IV1: 53387 | IW1: 53418 | IX1: 53448 | IY1: 53479 | IZ1: 53509 | JA1: 53540 | JB1: 53571 | JC1: 53601 | JD1: 53632 | JE1: 53662 | JF1: 53693 | JG1: 53724 | JH1: 53752 | JI1: 53783 | JJ1: 53813 | JK1: 53844 | JL1: 53874 | JM1: 53905 | JN1: 53936 | JO1: 53966 | JP1: 53997 | JQ1: 54027 | JR1: 54058 | JS1: 54089 | JT1: 54118 | JU1: 54149 | JV1: 54179 | JW1: 54210 | JX1: 54240 | JY1: 54271 | JZ1: 54302 | KA1: 54332 | KB1: 54363 | KC1: 54393 | KD1: 54424 | KE1: 54455 | KF1: 54483 | KG1: 54514 | KH1: 54544 | KI1: 54575 | KJ1: 54605 | KK1: 54636 | KL1: 54667 | KM1: 54697 | KN1: 54728 | KO1: 54758 | KP1: 54789 | KQ1: 54820 | KR1: 54848 | KS1: 54879 | KT1: 54909 | KU1: 54940 | KV1: 54970 | KW1: 55001 | KX1: 55032 | KY1: 55062 | KZ1: 55093 | LA1: 55123
N2: 841.92384 | O2: 951.48896 | P2: 1013.6364 | Q2: 875.76472 | R2: 925.39946 | S2: 781.42369 | T2: 884.55748 | U2: 1003.6554 | V2: 894.56467 | W2: 1027.8164 | X2: 940.16771 | Y2: 1100.8869 | Z2: 838.02203 | AA2: 947.07768 | AB2: 1008.9351 | AC2: 871.70137 | AD2: 921.10416 | AE2: 777.79526 | AF2: 880.44857 | AG2: 998.99147 | AH2: 890.40605 | AI2: 1023.0365 | AJ2: 935.7937 | AK2: 1095.7632 | AL2: 834.12022 | AM2: 942.6664 | AN2: 1004.2339 | AO2: 867.63802 | AP2: 916.80885 | AQ2: 774.16683 | AR2: 876.33966 | AS2: 994.32752 | AT2: 886.24744 | AU2: 1018.2566 | AV2: 931.4197 | AW2: 1090.6395 | AX2: 830.21841 | AY2: 938.25512 | AZ2: 999.5327 | BA2: 863.57467 | BB2: 912.51355 | BC2: 770.53839 | BD2: 872.23075 | BE2: 989.66358 | BF2: 882.08882 | BG2: 1013.4767 | BH2: 927.0457 | BI2: 1085.5158 | BJ2: 826.3166 | BK2: 933.84383 | BL2: 994.83147 | BM2: 859.51132 | BN2: 908.21824 | BO2: 766.90996 | BP2: 868.12183 | BQ2: 984.99963 | BR2: 877.9302 | BS2: 1008.6967 | BT2: 922.67169 | BU2: 1080.392 | BV2: 822.41479 | BW2: 929.43255 | BX2: 990.13025 | BY2: 855.44797 | BZ2: 903.92294 | CA2: 763.28152 | CB2: 864.01292 | CC2: 980.33568 | CD2: 873.77159 | CE2: 1003.9168 | CF2: 918.29769 | CG2: 1075.2683 | CH2: 818.51298 | CI2: 925.02127 | CJ2: 985.42902 | CK2: 851.38462 | CL2: 899.62764 | CM2: 759.65309 | CN2: 859.90401 | CO2: 975.67174 | CP2: 869.61297 | CQ2: 999.1369 | CR2: 913.92369 | CS2: 1070.1446 | CT2: 814.61117 | CU2: 920.60999 | CV2: 980.7278 | CW2: 847.32127 | CX2: 895.33233 | CY2: 756.02465 | CZ2: 855.7951 | DA2: 971.00779 | DB2: 865.45435 | DC2: 994.35698 | DD2: 909.54968 | DE2: 1065.0209 | DF2: 810.70936 | DG2: 916.19871 | DH2: 976.02657 | DI2: 843.25792 | DJ2: 891.03703 | DK2: 752.39622 | DL2: 851.68618 | DM2: 966.34384 | DN2: 861.29574 | DO2: 989.57705 | DP2: 905.17568 | DQ2: 1059.8972 | DR2: 806.80755 | DS2: 911.78742 | DT2: 971.32535 | DU2: 839.19457 | DV2: 886.74172 | DW2: 748.76778 | DX2: 847.57727 | DY2: 961.6799 | DZ2: 857.13712 | EA2: 984.79713 | EB2: 900.80168 | EC2: 1054.7735 | ED2: 802.90574 | EE2: 907.37614 | EF2: 966.62412 | EG2: 835.13122 | EH2: 882.44642 | EI2: 745.13935 | EJ2: 843.46836 | EK2: 957.01595 | EL2: 852.9785 | EM2: 980.0172 | EN2: 896.42767 | EO2: 1049.6498 | EP2: 799.00393 | EQ2: 902.96486 | ER2: 961.9229 | ES2: 831.06787 | ET2: 878.15111 | EU2: 741.51091 | EV2: 839.35945 | EW2: 952.352 | EX2: 848.81989 | EY2: 975.23728 | EZ2: 892.05367 | FA2: 1044.526 | FB2: 795.10212 | FC2: 898.55358 | FD2: 957.22167 | FE2: 827.00452 | FF2: 873.85581 | FG2: 737.88248 | FH2: 835.25054 | FI2: 947.68806 | FJ2: 844.66127 | FK2: 970.45736 | FL2: 887.67967 | FM2: 1039.4023 | FN2: 791.20031 | FO2: 894.1423 | FP2: 952.52045 | FQ2: 822.94117 | FR2: 869.56051 | FS2: 734.25405 | FT2: 831.14162 | FU2: 943.02411 | FV2: 840.50265 | FW2: 965.67743 | FX2: 883.30566 | FY2: 1034.2786 | FZ2: 787.2985 | GA2: 889.73102 | GB2: 947.81922 | GC2: 818.87782 | GD2: 865.2652 | GE2: 730.62561 | GF2: 827.03271 | GG2: 938.36016 | GH2: 836.34404 | GI2: 960.89751 | GJ2: 878.93166 | GK2: 1029.1549 | GL2: 783.39669 | GM2: 885.31973 | GN2: 943.118 | GO2: 814.81447 | GP2: 860.9699 | GQ2: 726.99718 | GR2: 822.9238 | GS2: 933.69622 | GT2: 832.18542 | GU2: 956.11758 | GV2: 874.55766 | GW2: 1024.0312 | GX2: 779.49488 | GY2: 880.90845 | GZ2: 938.41677 | HA2: 810.75112 | HB2: 856.67459 | HC2: 723.36874 | HD2: 818.81489 | HE2: 929.03227 | HF2: 828.0268 | HG2: 951.33766 | HH2: 870.18365 | HI2: 1018.9075 | HJ2: 775.59307 | HK2: 876.49717 | HL2: 933.71554 | HM2: 806.68777 | HN2: 852.37929 | HO2: 719.74031 | HP2: 814.70598 | HQ2: 924.36832 | HR2: 823.86819 | HS2: 946.55774 | HT2: 865.80965 | HU2: 1013.7838 | HV2: 771.69126 | HW2: 872.08589 | HX2: 929.01432 | HY2: 802.62443 | HZ2: 848.08398 | IA2: 716.11187 | IB2: 810.59706 | IC2: 919.70438 | ID2: 819.70957 | IE2: 941.77781 | IF2: 861.43565 | IG2: 1008.66 | IH2: 767.78945 | II2: 867.67461 | IJ2: 924.31309 | IK2: 798.56108 | IL2: 843.78868 | IM2: 712.48344 | IN2: 806.48815 | IO2: 915.04043 | IP2: 815.55095 | IQ2: 936.99789 | IR2: 857.06164 | IS2: 1003.5363 | IT2: 763.88764 | IU2: 863.26333 | IV2: 919.61187 | IW2: 794.49773 | IX2: 839.49337 | IY2: 708.855 | IZ2: 802.37924 | JA2: 910.37648 | JB2: 811.39234 | JC2: 932.21796 | JD2: 852.68764 | JE2: 998.41262 | JF2: 759.98583 | JG2: 858.85204 | JH2: 914.91064 | JI2: 790.43438 | JJ2: 835.19807 | JK2: 705.22657 | JL2: 798.27033 | JM2: 905.71254 | JN2: 807.23372 | JO2: 927.43804 | JP2: 848.31364 | JQ2: 993.2889 | JR2: 756.08402 | JS2: 854.44076 | JT2: 910.20942 | JU2: 786.37103 | JV2: 830.90277 | JW2: 701.59813 | JX2: 794.16141 | JY2: 901.04859 | JZ2: 803.0751 | KA2: 922.65812 | KB2: 843.93963 | KC2: 988.16519 | KD2: 752.18221 | KE2: 850.02948 | KF2: 905.50819 | KG2: 782.30768 | KH2: 826.60746 | KI2: 697.9697 | KJ2: 790.0525 | KK2: 896.38464 | KL2: 798.91649 | KM2: 917.87819 | KN2: 839.56563 | KO2: 983.04148 | KP2: 748.2804 | KQ2: 845.6182 | KR2: 900.80697 | KS2: 778.24433 | KT2: 822.31216 | KU2: 694.34127 | KV2: 785.94359 | KW2: 891.7207 | KX2: 794.75787 | KY2: 913.09827 | KZ2: 835.19163 | LA2: 977.91776
N3: 854.23009 | O3: 892.94429 | P3: 848.528 | Q3: 838.3522 | R3: 798.8867 | S3: 759.45851 | T3: 881.05836 | U3: 921.59711 | V3: 877.29182 | W3: 954.81628 | X3: 1009.8679 | Y3: 919.83429 | Z3: 849.34455 | AA3: 887.83489 | AB3: 843.67044 | AC3: 833.5506 | AD3: 794.30895 | AE3: 755.10461 | AF3: 876.00493 | AG3: 916.30864 | AH3: 872.25517 | AI3: 949.33194 | AJ3: 1004.0646 | AK3: 914.54581 | AL3: 844.459 | AM3: 882.7255 | AN3: 838.81287 | AO3: 828.749 | AP3: 789.7312 | AQ3: 750.75071 | AR3: 870.95149 | AS3: 911.02016 | AT3: 867.21853 | AU3: 943.84759 | AV3: 998.26124 | AW3: 909.25733 | AX3: 839.57346 | AY3: 877.6161 | AZ3: 833.95531 | BA3: 823.9474 | BB3: 785.15345 | BC3: 746.39681 | BD3: 865.89806 | BE3: 905.73168 | BF3: 862.18188 | BG3: 938.36324 | BH3: 992.4579 | BI3: 903.96886 | BJ3: 834.68791 | BK3: 872.50671 | BL3: 829.09775 | BM3: 819.14579 | BN3: 780.5757 | BO3: 742.04291 | BP3: 860.84463 | BQ3: 900.44321 | BR3: 857.14524 | BS3: 932.8789 | BT3: 986.65457 | BU3: 898.68038 | BV3: 829.80237 | BW3: 867.39731 | BX3: 824.24018 | BY3: 814.34419 | BZ3: 775.99795 | CA3: 737.68902 | CB3: 855.7912 | CC3: 895.15473 | CD3: 852.1086 | CE3: 927.39455 | CF3: 980.85124 | CG3: 893.39191 | CH3: 824.91682 | CI3: 862.28792 | CJ3: 819.38262 | CK3: 809.54259 | CL3: 771.4202 | CM3: 733.33512 | CN3: 850.73776 | CO3: 889.86626 | CP3: 847.07195 | CQ3: 921.91021 | CR3: 975.0479 | CS3: 888.10343 | CT3: 820.03128 | CU3: 857.17852 | CV3: 814.52506 | CW3: 804.74099 | CX3: 766.84245 | CY3: 728.98122 | CZ3: 845.68433 | DA3: 884.57778 | DB3: 842.03531 | DC3: 916.42586 | DD3: 969.24457 | DE3: 882.81495 | DF3: 815.14573 | DG3: 852.06912 | DH3: 809.66749 | DI3: 799.93939 | DJ3: 762.2647 | DK3: 724.62732 | DL3: 840.6309 | DM3: 879.2893 | DN3: 836.99866 | DO3: 910.94152 | DP3: 963.44124 | DQ3: 877.52648 | DR3: 810.26019 | DS3: 846.95973 | DT3: 804.80993 | DU3: 795.13779 | DV3: 757.68695 | DW3: 720.27342 | DX3: 835.57746 | DY3: 874.00083 | DZ3: 831.96202 | EA3: 905.45717 | EB3: 957.6379 | EC3: 872.238 | ED3: 805.37464 | EE3: 841.85033 | EF3: 799.95237 | EG3: 790.33619 | EH3: 753.1092 | EI3: 715.91952 | EJ3: 830.52403 | EK3: 868.71235 | EL3: 826.92537 | EM3: 899.97282 | EN3: 951.83457 | EO3: 866.94952 | EP3: 800.4891 | EQ3: 836.74094 | ER3: 795.0948 | ES3: 785.53459 | ET3: 748.53145 | EU3: 711.56562 | EV3: 825.4706 | EW3: 863.42387 | EX3: 821.88873 | EY3: 894.48848 | EZ3: 946.03124 | FA3: 861.66105 | FB3: 795.60355 | FC3: 831.63154 | FD3: 790.23724 | FE3: 780.73299 | FF3: 743.9537 | FG3: 707.21172 | FH3: 820.41717 | FI3: 858.1354 | FJ3: 816.85209 | FK3: 889.00413 | FL3: 940.2279 | FM3: 856.37257 | FN3: 790.71801 | FO3: 826.52215 | FP3: 785.37968 | FQ3: 775.93139 | FR3: 739.37595 | FS3: 702.85782 | FT3: 815.36373 | FU3: 852.84692 | FV3: 811.81544 | FW3: 883.51979 | FX3: 934.42457 | FY3: 851.0841 | FZ3: 785.83246 | GA3: 821.41275 | GB3: 780.52211 | GC3: 771.12979 | GD3: 734.7982 | GE3: 698.50393 | GF3: 810.3103 | GG3: 847.55845 | GH3: 806.7788 | GI3: 878.03544 | GJ3: 928.62124 | GK3: 845.79562 | GL3: 780.94692 | GM3: 816.30336 | GN3: 775.66455 | GO3: 766.32819 | GP3: 730.22045 | GQ3: 694.15003 | GR3: 805.25687 | GS3: 842.26997 | GT3: 801.74215 | GU3: 872.5511 | GV3: 922.81791 | GW3: 840.50714 | GX3: 776.06138 | GY3: 811.19396 | GZ3: 770.80699 | HA3: 761.52659 | HB3: 725.6427 | HC3: 689.79613 | HD3: 800.20343 | HE3: 836.98149 | HF3: 796.70551 | HG3: 867.06675 | HH3: 917.01457 | HI3: 835.21867 | HJ3: 771.17583 | HK3: 806.08456 | HL3: 765.94942 | HM3: 756.72499 | HN3: 721.06495 | HO3: 685.44223 | HP3: 795.15 | HQ3: 831.69302 | HR3: 791.66887 | HS3: 861.5824 | HT3: 911.21124 | HU3: 829.93019 | HV3: 766.29029 | HW3: 800.97517 | HX3: 761.09186 | HY3: 751.92339 | HZ3: 716.4872 | IA3: 681.08833 | IB3: 790.09657 | IC3: 826.40454 | ID3: 786.63222 | IE3: 856.09806 | IF3: 905.40791 | IG3: 824.64171 | IH3: 761.40474 | II3: 795.86577 | IJ3: 756.2343 | IK3: 747.12179 | IL3: 711.90945 | IM3: 676.73443 | IN3: 785.04314 | IO3: 821.11606 | IP3: 781.59558 | IQ3: 850.61371 | IR3: 899.60457 | IS3: 819.35324 | IT3: 756.5192 | IU3: 790.75638 | IV3: 751.37673 | IW3: 742.32018 | IX3: 707.3317 | IY3: 672.38053 | IZ3: 779.9897 | JA3: 815.82759 | JB3: 776.55893 | JC3: 845.12937 | JD3: 893.80124 | JE3: 814.06476 | JF3: 751.63365 | JG3: 785.64698 | JH3: 746.51917 | JI3: 737.51858 | JJ3: 702.75395 | JK3: 668.02663 | JL3: 774.93627 | JM3: 810.53911 | JN3: 771.52229 | JO3: 839.64502 | JP3: 887.99791 | JQ3: 808.77629 | JR3: 746.74811 | JS3: 780.53759 | JT3: 741.66161 | JU3: 732.71698 | JV3: 698.1762 | JW3: 663.67273 | JX3: 769.88284 | JY3: 805.25064 | JZ3: 766.48565 | KA3: 834.16068 | KB3: 882.19457 | KC3: 803.48781 | KD3: 741.86256 | KE3: 775.42819 | KF3: 736.80404 | KG3: 727.91538 | KH3: 693.59845 | KI3: 659.31883 | KJ3: 764.8294 | KK3: 799.96216 | KL3: 761.449 | KM3: 828.67633 | KN3: 876.39124 | KO3: 798.19933 | KP3: 736.97702 | KQ3: 770.3188 | KR3: 731.94648 | KS3: 723.11378 | KT3: 689.0207 | KU3: 654.96494 | KV3: 759.77597 | KW3: 794.67368 | KX3: 756.41236 | KY3: 823.19198 | KZ3: 870.58791 | LA3: 792.91086
N4: 698.10586 | O4: 726.33294 | P4: 699.69877 | Q4: 692.50283 | R4: 666.20343 | S4: 635.81471 | T4: 720.59284 | U4: 785.81576 | V4: 730.9592 | W4: 786.43545 | X4: 826.02779 | Y4: 748.5692 | Z4: 694.1265 | AA4: 722.19071 | AB4: 695.70654 | AC4: 688.54978 | AD4: 662.3987 | AE4: 632.1818 | AF4: 716.47356 | AG4: 781.32149 | AH4: 726.77668 | AI4: 781.93335 | AJ4: 821.29677 | AK4: 744.27977 | AL4: 690.14714 | AM4: 718.04849 | AN4: 691.71432 | AO4: 684.59673 | AP4: 658.59396 | AQ4: 628.54889 | AR4: 712.35428 | AS4: 776.82723 | AT4: 722.59416 | AU4: 777.43125 | AV4: 816.56576 | AW4: 739.99035 | AX4: 686.16779 | AY4: 713.90626 | AZ4: 687.72209 | BA4: 680.64367 | BB4: 654.78922 | BC4: 624.91598 | BD4: 708.235 | BE4: 772.33296 | BF4: 718.41163 | BG4: 772.92914 | BH4: 811.83475 | BI4: 735.70093 | BJ4: 682.18843 | BK4: 709.76404 | BL4: 683.72986 | BM4: 676.69062 | BN4: 650.98449 | BO4: 621.28306 | BP4: 704.11572 | BQ4: 767.83869 | BR4: 714.22911 | BS4: 768.42704 | BT4: 807.10373 | BU4: 731.41151 | BV4: 678.20907 | BW4: 705.62181 | BX4: 679.73763 | BY4: 672.73757 | BZ4: 647.17975 | CA4: 617.65015 | CB4: 699.99645 | CC4: 763.34443 | CD4: 710.04659 | CE4: 763.92494 | CF4: 802.37272 | CG4: 727.12208 | CH4: 674.22971 | CI4: 701.47959 | CJ4: 675.7454 | CK4: 668.78452 | CL4: 643.37502 | CM4: 614.01724 | CN4: 695.87717 | CO4: 758.85016 | CP4: 705.86406 | CQ4: 759.42284 | CR4: 797.64171 | CS4: 722.83266 | CT4: 670.25036 | CU4: 697.33736 | CV4: 671.75317 | CW4: 664.83147 | CX4: 639.57028 | CY4: 610.38433 | CZ4: 691.75789 | DA4: 754.35589 | DB4: 701.68154 | DC4: 754.92073 | DD4: 792.91069 | DE4: 718.54324 | DF4: 666.271 | DG4: 693.19513 | DH4: 667.76094 | DI4: 660.87841 | DJ4: 635.76555 | DK4: 606.75141 | DL4: 687.63861 | DM4: 749.86163 | DN4: 697.49902 | DO4: 750.41863 | DP4: 788.17968 | DQ4: 714.25382 | DR4: 662.29164 | DS4: 689.05291 | DT4: 663.76871 | DU4: 656.92536 | DV4: 631.96081 | DW4: 603.1185 | DX4: 683.51933 | DY4: 745.36736 | DZ4: 693.3165 | EA4: 745.91653 | EB4: 783.44866 | EC4: 709.96439 | ED4: 658.31229 | EE4: 684.91068 | EF4: 659.77648 | EG4: 652.97231 | EH4: 628.15608 | EI4: 599.48559 | EJ4: 679.40006 | EK4: 740.87309 | EL4: 689.13397 | EM4: 741.41443 | EN4: 778.71765 | EO4: 705.67497 | EP4: 654.33293 | EQ4: 680.76846 | ER4: 655.78425 | ES4: 649.01926 | ET4: 624.35134 | EU4: 595.85268 | EV4: 675.28078 | EW4: 736.37883 | EX4: 684.95145 | EY4: 736.91232 | EZ4: 773.98664 | FA4: 701.38555 | FB4: 650.35357 | FC4: 676.62623 | FD4: 651.79202 | FE4: 645.06621 | FF4: 620.5466 | FG4: 592.21977 | FH4: 671.1615 | FI4: 731.88456 | FJ4: 680.76893 | FK4: 732.41022 | FL4: 769.25562 | FM4: 697.09613 | FN4: 646.37421 | FO4: 672.48401 | FP4: 647.79979 | FQ4: 641.11315 | FR4: 616.74187 | FS4: 588.58685 | FT4: 667.04222 | FU4: 727.39029 | FV4: 676.58641 | FW4: 727.90812 | FX4: 764.52461 | FY4: 692.8067 | FZ4: 642.39486 | GA4: 668.34178 | GB4: 643.80756 | GC4: 637.1601 | GD4: 612.93713 | GE4: 584.95394 | GF4: 662.92294 | GG4: 722.89602 | GH4: 672.40388 | GI4: 723.40602 | GJ4: 759.7936 | GK4: 688.51728 | GL4: 638.4155 | GM4: 664.19956 | GN4: 639.81533 | GO4: 633.20705 | GP4: 609.1324 | GQ4: 581.32103 | GR4: 658.80366 | GS4: 718.40176 | GT4: 668.22136 | GU4: 718.90391 | GV4: 755.06258 | GW4: 684.22786 | GX4: 634.43614 | GY4: 660.05733 | GZ4: 635.8231 | HA4: 629.254 | HB4: 605.32766 | HC4: 577.68812 | HD4: 654.68439 | HE4: 713.90749 | HF4: 664.03884 | HG4: 714.40181 | HH4: 750.33157 | HI4: 679.93844 | HJ4: 630.45679 | HK4: 655.91511 | HL4: 631.83087 | HM4: 625.30095 | HN4: 601.52293 | HO4: 574.0552 | HP4: 650.56511 | HQ4: 709.41322 | HR4: 659.85632 | HS4: 709.89971 | HT4: 745.60056 | HU4: 675.64902 | HV4: 626.47743 | HW4: 651.77288 | HX4: 627.83864 | HY4: 621.34789 | HZ4: 597.71819 | IA4: 570.42229 | IB4: 646.44583 | IC4: 704.91896 | ID4: 655.67379 | IE4: 705.39761 | IF4: 740.86954 | IG4: 671.35959 | IH4: 622.49807 | II4: 647.63066 | IJ4: 623.84641 | IK4: 617.39484 | IL4: 593.91346 | IM4: 566.78938 | IN4: 642.32655 | IO4: 700.42469 | IP4: 651.49127 | IQ4: 700.8955 | IR4: 736.13853 | IS4: 667.07017 | IT4: 618.51871 | IU4: 643.48843 | IV4: 619.85418 | IW4: 613.44179 | IX4: 590.10872 | IY4: 563.15647 | IZ4: 638.20727 | JA4: 695.93042 | JB4: 647.30875 | JC4: 696.3934 | JD4: 731.40752 | JE4: 662.78075 | JF4: 614.53936 | JG4: 639.3462 | JH4: 615.86195 | JI4: 609.48874 | JJ4: 586.30398 | JK4: 559.52355 | JL4: 634.08799 | JM4: 691.43616 | JN4: 643.12623 | JO4: 691.8913 | JP4: 726.6765 | JQ4: 658.49133 | JR4: 610.56 | JS4: 635.20398 | JT4: 611.86972 | JU4: 605.53569 | JV4: 582.49925 | JW4: 555.89064 | JX4: 629.96872 | JY4: 686.94189 | JZ4: 638.9437 | KA4: 687.3892 | KB4: 721.94549 | KC4: 654.2019 | KD4: 606.58064 | KE4: 631.06175 | KF4: 607.87749 | KG4: 601.58263 | KH4: 578.69451 | KI4: 552.25773 | KJ4: 625.84944 | KK4: 682.44762 | KL4: 634.76118 | KM4: 682.88709 | KN4: 717.21448 | KO4: 649.91248 | KP4: 602.60129 | KQ4: 626.91953 | KR4: 603.88526 | KS4: 597.62958 | KT4: 574.88978 | KU4: 548.62482 | KV4: 621.73016 | KW4: 677.95336 | KX4: 630.57866 | KY4: 678.38499 | KZ4: 712.48346 | LA4: 645.62306
N5: 310.65845 | O5: 249.94959 | P5: 306.9303 | Q5: 266.85292 | R5: 286.641 | S5: 324.58165 | T5: 362.99799 | U5: 331.98258 | V5: 271.41082 | W5: 330.25232 | X5: 263.20978 | Y5: 262.81928 | Z5: 309.38786 | AA5: 248.92695 | AB5: 305.6741 | AC5: 265.76038 | AD5: 285.46705 | AE5: 323.25186 | AF5: 361.51029 | AG5: 330.62153 | AH5: 270.29772 | AI5: 328.89743 | AJ5: 262.12958 | AK5: 261.74031 | AL5: 308.11728 | AM5: 247.90432 | AN5: 304.41791 | AO5: 264.66784 | AP5: 284.29309 | AQ5: 321.92206 | AR5: 360.02259 | AS5: 329.26048 | AT5: 269.18462 | AU5: 327.54255 | AV5: 261.04937 | AW5: 260.66134 | AX5: 306.84669 | AY5: 246.88168 | AZ5: 303.16171 | BA5: 263.5753 | BB5: 283.11913 | BC5: 320.59226 | BD5: 358.5349 | BE5: 327.89943 | BF5: 268.07152 | BG5: 326.18767 | BH5: 259.96917 | BI5: 259.58237 | BJ5: 305.5761 | BK5: 245.85904 | BL5: 301.90552 | BM5: 262.48276 | BN5: 281.94518 | BO5: 319.26246 | BP5: 357.0472 | BQ5: 326.53839 | BR5: 266.95842 | BS5: 324.83279 | BT5: 258.88896 | BU5: 258.5034 | BV5: 304.30552 | BW5: 244.8364 | BX5: 300.64932 | BY5: 261.39022 | BZ5: 280.77122 | CA5: 317.93266 | CB5: 355.5595 | CC5: 325.17734 | CD5: 265.84532 | CE5: 323.47791 | CF5: 257.80876 | CG5: 257.42443 | CH5: 303.03493 | CI5: 243.81377 | CJ5: 299.39313 | CK5: 260.29768 | CL5: 279.59727 | CM5: 316.60286 | CN5: 354.07181 | CO5: 323.81629 | CP5: 264.73222 | CQ5: 322.12303 | CR5: 256.72855 | CS5: 256.34546 | CT5: 301.76434 | CU5: 242.79113 | CV5: 298.13693 | CW5: 259.20514 | CX5: 278.42331 | CY5: 315.27306 | CZ5: 352.58411 | DA5: 322.45524 | DB5: 263.61912 | DC5: 320.76815 | DD5: 255.64835 | DE5: 255.26649 | DF5: 300.49376 | DG5: 241.76849 | DH5: 296.88074 | DI5: 258.1126 | DJ5: 277.24935 | DK5: 313.94327 | DL5: 351.09641 | DM5: 321.09419 | DN5: 262.50602 | DO5: 319.41327 | DP5: 254.56815 | DQ5: 254.18752 | DR5: 299.22317 | DS5: 240.74586 | DT5: 295.62454 | DU5: 257.02006 | DV5: 276.0754 | DW5: 312.61347 | DX5: 349.60872 | DY5: 319.73314 | DZ5: 261.39292 | EA5: 318.05838 | EB5: 253.48794 | EC5: 253.10855 | ED5: 297.95258 | EE5: 239.72322 | EF5: 294.36835 | EG5: 255.92752 | EH5: 274.90144 | EI5: 311.28367 | EJ5: 348.12102 | EK5: 318.37209 | EL5: 260.27982 | EM5: 316.7035 | EN5: 252.40774 | EO5: 252.02958 | EP5: 296.682 | EQ5: 238.70058 | ER5: 293.11215 | ES5: 254.83498 | ET5: 273.72748 | EU5: 309.95387 | EV5: 346.63332 | EW5: 317.01104 | EX5: 259.16672 | EY5: 315.34862 | EZ5: 251.32753 | FA5: 250.95061 | FB5: 295.41141 | FC5: 237.67794 | FD5: 291.85596 | FE5: 253.74244 | FF5: 272.55353 | FG5: 308.62407 | FH5: 345.14563 | FI5: 315.64999 | FJ5: 258.05362 | FK5: 313.99374 | FL5: 250.24733 | FM5: 249.87164 | FN5: 294.14082 | FO5: 236.65531 | FP5: 290.59976 | FQ5: 252.6499 | FR5: 271.37957 | FS5: 307.29427 | FT5: 343.65793 | FU5: 314.28894 | FV5: 256.94052 | FW5: 312.63886 | FX5: 249.16712 | FY5: 248.79266 | FZ5: 292.87024 | GA5: 235.63267 | GB5: 289.34357 | GC5: 251.55736 | GD5: 270.20561 | GE5: 305.96448 | GF5: 342.17023 | GG5: 312.92789 | GH5: 255.82743 | GI5: 311.28398 | GJ5: 248.08692 | GK5: 247.71369 | GL5: 291.59965 | GM5: 234.61003 | GN5: 288.08737 | GO5: 250.46482 | GP5: 269.03166 | GQ5: 304.63468 | GR5: 340.68254 | GS5: 311.56684 | GT5: 254.71433 | GU5: 309.9291 | GV5: 247.00672 | GW5: 246.63472 | GX5: 290.32906 | GY5: 233.58739 | GZ5: 286.83118 | HA5: 249.37228 | HB5: 267.8577 | HC5: 303.30488 | HD5: 339.19484 | HE5: 310.20579 | HF5: 253.60123 | HG5: 308.57421 | HH5: 245.92651 | HI5: 245.55575 | HJ5: 289.05848 | HK5: 232.56476 | HL5: 285.57499 | HM5: 248.27974 | HN5: 266.68375 | HO5: 301.97508 | HP5: 337.70714 | HQ5: 308.84475 | HR5: 252.48813 | HS5: 307.21933 | HT5: 244.84631 | HU5: 244.47678 | HV5: 287.78789 | HW5: 231.54212 | HX5: 284.31879 | HY5: 247.1872 | HZ5: 265.50979 | IA5: 300.64528 | IB5: 336.21945 | IC5: 307.4837 | ID5: 251.37503 | IE5: 305.86445 | IF5: 243.7661 | IG5: 243.39781 | IH5: 286.5173 | II5: 230.51948 | IJ5: 283.0626 | IK5: 246.09466 | IL5: 264.33583 | IM5: 299.31548 | IN5: 334.73175 | IO5: 306.12265 | IP5: 250.26193 | IQ5: 304.50957 | IR5: 242.6859 | IS5: 242.31884 | IT5: 285.24672 | IU5: 229.49685 | IV5: 281.8064 | IW5: 245.00212 | IX5: 263.16188 | IY5: 297.98568 | IZ5: 333.24405 | JA5: 304.7616 | JB5: 249.14883 | JC5: 303.15469 | JD5: 241.60569 | JE5: 241.23987 | JF5: 283.97613 | JG5: 228.47421 | JH5: 280.55021 | JI5: 243.90958 | JJ5: 261.98792 | JK5: 296.65589 | JL5: 331.75636 | JM5: 303.40055 | JN5: 248.03573 | JO5: 301.79981 | JP5: 240.52549 | JQ5: 240.1609 | JR5: 282.70554 | JS5: 227.45157 | JT5: 279.29401 | JU5: 242.81704 | JV5: 260.81396 | JW5: 295.32609 | JX5: 330.26866 | JY5: 302.0395 | JZ5: 246.92263 | KA5: 300.44493 | KB5: 239.44529 | KC5: 239.08193 | KD5: 281.43496 | KE5: 226.42893 | KF5: 278.03782 | KG5: 241.7245 | KH5: 259.64001 | KI5: 293.99629 | KJ5: 328.78096 | KK5: 300.67845 | KL5: 245.80953 | KM5: 299.09005 | KN5: 238.36508 | KO5: 238.00296 | KP5: 280.16437 | KQ5: 225.4063 | KR5: 276.78162 | KS5: 240.63196 | KT5: 258.46605 | KU5: 292.66649 | KV5: 327.29327 | KW5: 299.3174 | KX5: 244.69643 | KY5: 297.73516 | KZ5: 237.28488 | LA5: 236.92399
N6: 774.43433 | O6: 713.13438 | P6: 775.9649 | Q6: 743.86147 | R6: 822.39233 | S6: 792.79185 | T6: 861.2266 | U6: 955.30424 | V6: 875.07721 | W6: 819.81822 | X6: 712.43773 | Y6: 706.19479 | Z6: 768.63126 | AA6: 707.7873 | AB6: 770.14308 | AC6: 738.27703 | AD6: 816.21446 | AE6: 786.83261 | AF6: 854.74889 | AG6: 948.11442 | AH6: 868.48706 | AI6: 813.64035 | AJ6: 707.06567 | AK6: 700.86646 | AL6: 762.82818 | AM6: 702.44023 | AN6: 764.32126 | AO6: 732.69258 | AP6: 810.03659 | AQ6: 780.87337 | AR6: 848.27118 | AS6: 940.9246 | AT6: 861.89692 | AU6: 807.46248 | AV6: 701.69361 | AW6: 695.53812 | AX6: 757.0251 | AY6: 697.09315 | AZ6: 758.49945 | BA6: 727.10813 | BB6: 803.85872 | BC6: 774.91413 | BD6: 841.79348 | BE6: 933.73478 | BF6: 855.30677 | BG6: 801.2846 | BH6: 696.32155 | BI6: 690.20979 | BJ6: 751.22203 | BK6: 691.74608 | BL6: 752.67763 | BM6: 721.52369 | BN6: 797.68085 | BO6: 768.95489 | BP6: 835.31577 | BQ6: 926.54497 | BR6: 848.71662 | BS6: 795.10673 | BT6: 690.94949 | BU6: 684.88145 | BV6: 745.41895 | BW6: 686.399 | BX6: 746.85582 | BY6: 715.93924 | BZ6: 791.50297 | CA6: 762.99565 | CB6: 828.83806 | CC6: 919.35515 | CD6: 842.12648 | CE6: 788.92886 | CF6: 685.57743 | CG6: 679.55312 | CH6: 739.61588 | CI6: 681.05192 | CJ6: 741.034 | CK6: 710.3548 | CL6: 785.3251 | CM6: 757.03641 | CN6: 822.36035 | CO6: 912.16533 | CP6: 835.53633 | CQ6: 782.75099 | CR6: 680.20536 | CS6: 674.22478 | CT6: 733.8128 | CU6: 675.70485 | CV6: 735.21218 | CW6: 704.77035 | CX6: 779.14723 | CY6: 751.07717 | CZ6: 815.88265 | DA6: 904.97551 | DB6: 828.94619 | DC6: 776.57312 | DD6: 674.8333 | DE6: 668.89644 | DF6: 728.00972 | DG6: 670.35777 | DH6: 729.39037 | DI6: 699.18591 | DJ6: 772.96936 | DK6: 745.11793 | DL6: 809.40494 | DM6: 897.78569 | DN6: 822.35604 | DO6: 770.39525 | DP6: 669.46124 | DQ6: 663.56811 | DR6: 722.20665 | DS6: 665.0107 | DT6: 723.56855 | DU6: 693.60146 | DV6: 766.79149 | DW6: 739.15869 | DX6: 802.92723 | DY6: 890.59588 | DZ6: 815.7659 | EA6: 764.21738 | EB6: 664.08918 | EC6: 658.23977 | ED6: 716.40357 | EE6: 659.66362 | EF6: 717.74674 | EG6: 688.01701 | EH6: 760.61362 | EI6: 733.19945 | EJ6: 796.44953 | EK6: 883.40606 | EL6: 809.17575 | EM6: 758.03951 | EN6: 658.71712 | EO6: 652.91144 | EP6: 710.6005 | EQ6: 654.31655 | ER6: 711.92492 | ES6: 682.43257 | ET6: 754.43575 | EU6: 727.2402 | EV6: 789.97182 | EW6: 876.21624 | EX6: 802.5856 | EY6: 751.86163 | EZ6: 653.34505 | FA6: 647.5831 | FB6: 704.79742 | FC6: 648.96947 | FD6: 706.1031 | FE6: 676.84812 | FF6: 748.25788 | FG6: 721.28096 | FH6: 783.49411 | FI6: 869.02642 | FJ6: 795.99546 | FK6: 745.68376 | FL6: 647.97299 | FM6: 642.25477 | FN6: 698.99434 | FO6: 643.62239 | FP6: 700.28129 | FQ6: 671.26368 | FR6: 742.08 | FS6: 715.32172 | FT6: 777.0164 | FU6: 861.83661 | FV6: 789.40531 | FW6: 739.50589 | FX6: 642.60093 | FY6: 636.92643 | FZ6: 693.19127 | GA6: 638.27532 | GB6: 694.45947 | GC6: 665.67923 | GD6: 735.90213 | GE6: 709.36248 | GF6: 770.5387 | GG6: 854.64679 | GH6: 782.81517 | GI6: 733.32802 | GJ6: 637.22887 | GK6: 631.59809 | GL6: 687.38819 | GM6: 632.92824 | GN6: 688.63766 | GO6: 660.09478 | GP6: 729.72426 | GQ6: 703.40324 | GR6: 764.06099 | GS6: 847.45697 | GT6: 776.22502 | GU6: 727.15015 | GV6: 631.85681 | GW6: 626.26976 | GX6: 681.58511 | GY6: 627.58117 | GZ6: 682.81584 | HA6: 654.51034 | HB6: 723.54639 | HC6: 697.444 | HD6: 757.58328 | HE6: 840.26715 | HF6: 769.63488 | HG6: 720.97228 | HH6: 626.48474 | HI6: 620.94142 | HJ6: 675.78204 | HK6: 622.23409 | HL6: 676.99402 | HM6: 648.92589 | HN6: 717.36852 | HO6: 691.48476 | HP6: 751.10557 | HQ6: 833.07733 | HR6: 763.04473 | HS6: 714.79441 | HT6: 621.11268 | HU6: 615.61309 | HV6: 669.97896 | HW6: 616.88702 | HX6: 671.17221 | HY6: 643.34145 | HZ6: 711.19065 | IA6: 685.52552 | IB6: 744.62787 | IC6: 825.88752 | ID6: 756.45458 | IE6: 708.61654 | IF6: 615.74062 | IG6: 610.28475 | IH6: 664.17589 | II6: 611.53994 | IJ6: 665.35039 | IK6: 637.757 | IL6: 705.01278 | IM6: 679.56628 | IN6: 738.15016 | IO6: 818.6977 | IP6: 749.86444 | IQ6: 702.43866 | IR6: 610.36856 | IS6: 604.95641 | IT6: 658.37281 | IU6: 606.19287 | IV6: 659.52858 | IW6: 632.17256 | IX6: 698.83491 | IY6: 673.60704 | IZ6: 731.67245 | JA6: 811.50788 | JB6: 743.27429 | JC6: 696.26079 | JD6: 604.9965 | JE6: 599.62808 | JF6: 652.56973 | JG6: 600.84579 | JH6: 653.70676 | JI6: 626.58811 | JJ6: 692.65704 | JK6: 667.6478 | JL6: 725.19475 | JM6: 804.31806 | JN6: 736.68415 | JO6: 690.08292 | JP6: 599.62443 | JQ6: 594.29974 | JR6: 646.76666 | JS6: 595.49871 | JT6: 647.88494 | JU6: 621.00366 | JV6: 686.47916 | JW6: 661.68856 | JX6: 718.71704 | JY6: 797.12825 | JZ6: 730.094 | KA6: 683.90505 | KB6: 594.25237 | KC6: 588.97141 | KD6: 640.96358 | KE6: 590.15164 | KF6: 642.06313 | KG6: 615.41922 | KH6: 680.30129 | KI6: 655.72932 | KJ6: 712.23933 | KK6: 789.93843 | KL6: 723.50386 | KM6: 677.72718 | KN6: 588.88031 | KO6: 583.64307 | KP6: 635.16051 | KQ6: 584.80456 | KR6: 636.24131 | KS6: 609.83477 | KT6: 674.12342 | KU6: 649.77007 | KV6: 705.76162 | KW6: 782.74861 | KX6: 716.91371 | KY6: 671.54931 | KZ6: 583.50825 | LA6: 578.31474
N7: 131.17733 | O7: 134.47232 | P7: 137.94551 | Q7: 133.43806 | R7: 134.3713 | S7: 141.73368 | T7: 152.43829 | U7: 162.86121 | V7: 160.07056 | W7: 137.4866 | X7: 117.54423 | Y7: 125.25448 | Z7: 130.42995 | AA7: 133.7058 | AB7: 137.15881 | AC7: 132.67671 | AD7: 133.60426 | AE7: 140.92423 | AF7: 151.56729 | AG7: 161.93021 | AH7: 159.15508 | AI7: 136.69991 | AJ7: 116.87133 | AK7: 124.53709 | AL7: 129.68256 | AM7: 132.93928 | AN7: 136.37212 | AO7: 131.91536 | AP7: 132.83722 | AQ7: 140.11478 | AR7: 150.69629 | AS7: 160.99921 | AT7: 158.2396 | AU7: 135.91322 | AV7: 116.19842 | AW7: 123.81971 | AX7: 128.93518 | AY7: 132.17275 | AZ7: 135.58543 | BA7: 131.15401 | BB7: 132.07018 | BC7: 139.30532 | BD7: 149.82529 | BE7: 160.06821 | BF7: 157.32412 | BG7: 135.12652 | BH7: 115.52552 | BI7: 123.10232 | BJ7: 128.18779 | BK7: 131.40623 | BL7: 134.79873 | BM7: 130.39266 | BN7: 131.30314 | BO7: 138.49587 | BP7: 148.95429 | BQ7: 159.13721 | BR7: 156.40864 | BS7: 134.33983 | BT7: 114.85261 | BU7: 122.38493 | BV7: 127.44041 | BW7: 130.63971 | BX7: 134.01204 | BY7: 129.63131 | BZ7: 130.5361 | CA7: 137.68642 | CB7: 148.08329 | CC7: 158.20621 | CD7: 155.49315 | CE7: 133.55314 | CF7: 114.17971 | CG7: 121.66755 | CH7: 126.69302 | CI7: 129.87319 | CJ7: 133.22535 | CK7: 128.86996 | CL7: 129.76906 | CM7: 136.87697 | CN7: 147.21229 | CO7: 157.27522 | CP7: 154.57767 | CQ7: 132.76644 | CR7: 113.5068 | CS7: 120.95016 | CT7: 125.94564 | CU7: 129.10667 | CV7: 132.43865 | CW7: 128.10861 | CX7: 129.00202 | CY7: 136.06752 | CZ7: 146.34128 | DA7: 156.34422 | DB7: 153.66219 | DC7: 131.97975 | DD7: 112.8339 | DE7: 120.23278 | DF7: 125.19825 | DG7: 128.34015 | DH7: 131.65196 | DI7: 127.34726 | DJ7: 128.23498 | DK7: 135.25807 | DL7: 145.47028 | DM7: 155.41322 | DN7: 152.74671 | DO7: 131.19305 | DP7: 112.161 | DQ7: 119.51539 | DR7: 124.45087 | DS7: 127.57362 | DT7: 130.86527 | DU7: 126.58591 | DV7: 127.46795 | DW7: 134.44862 | DX7: 144.59928 | DY7: 154.48222 | DZ7: 151.83123 | EA7: 130.40636 | EB7: 111.48809 | EC7: 118.79801 | ED7: 123.70348 | EE7: 126.8071 | EF7: 130.07857 | EG7: 125.82456 | EH7: 126.70091 | EI7: 133.63917 | EJ7: 143.72828 | EK7: 153.55122 | EL7: 150.91575 | EM7: 129.61967 | EN7: 110.81519 | EO7: 118.08062 | EP7: 122.9561 | EQ7: 126.04058 | ER7: 129.29188 | ES7: 125.06321 | ET7: 125.93387 | EU7: 132.82972 | EV7: 142.85728 | EW7: 152.62023 | EX7: 150.00026 | EY7: 128.83297 | EZ7: 110.14228 | FA7: 117.36323 | FB7: 122.20871 | FC7: 125.27406 | FD7: 128.50519 | FE7: 124.30186 | FF7: 125.16683 | FG7: 132.02026 | FH7: 141.98628 | FI7: 151.68923 | FJ7: 149.08478 | FK7: 128.04628 | FL7: 109.46938 | FM7: 116.64585 | FN7: 121.46133 | FO7: 124.50754 | FP7: 127.71849 | FQ7: 123.54051 | FR7: 124.39979 | FS7: 131.21081 | FT7: 141.11528 | FU7: 150.75823 | FV7: 148.1693 | FW7: 127.25959 | FX7: 108.79647 | FY7: 115.92846 | FZ7: 120.71395 | GA7: 123.74101 | GB7: 126.9318 | GC7: 122.77916 | GD7: 123.63275 | GE7: 130.40136 | GF7: 140.24428 | GG7: 149.82723 | GH7: 147.25382 | GI7: 126.47289 | GJ7: 108.12357 | GK7: 115.21108 | GL7: 119.96656 | GM7: 122.97449 | GN7: 126.14511 | GO7: 122.01781 | GP7: 122.86571 | GQ7: 129.59191 | GR7: 139.37328 | GS7: 148.89623 | GT7: 146.33834 | GU7: 125.6862 | GV7: 107.45066 | GW7: 114.49369 | GX7: 119.21918 | GY7: 122.20797 | GZ7: 125.35841 | HA7: 121.25646 | HB7: 122.09867 | HC7: 128.78246 | HD7: 138.50228 | HE7: 147.96523 | HF7: 145.42286 | HG7: 124.89951 | HH7: 106.77776 | HI7: 113.7763 | HJ7: 118.47179 | HK7: 121.44145 | HL7: 124.57172 | HM7: 120.49511 | HN7: 121.33163 | HO7: 127.97301 | HP7: 137.63128 | HQ7: 147.03424 | HR7: 144.50738 | HS7: 124.11281 | HT7: 106.10485 | HU7: 113.05892 | HV7: 117.72441 | HW7: 120.67493 | HX7: 123.78502 | HY7: 119.73376 | HZ7: 120.56459 | IA7: 127.16356 | IB7: 136.76028 | IC7: 146.10324 | ID7: 143.59189 | IE7: 123.32612 | IF7: 105.43195 | IG7: 112.34153 | IH7: 116.97702 | II7: 119.9084 | IJ7: 122.99833 | IK7: 118.97241 | IL7: 119.79755 | IM7: 126.35411 | IN7: 135.88928 | IO7: 145.17224 | IP7: 142.67641 | IQ7: 122.53943 | IR7: 104.75904 | IS7: 111.62415 | IT7: 116.22964 | IU7: 119.14188 | IV7: 122.21164 | IW7: 118.21107 | IX7: 119.03052 | IY7: 125.54465 | IZ7: 135.01828 | JA7: 144.24124 | JB7: 141.76093 | JC7: 121.75273 | JD7: 104.08614 | JE7: 110.90676 | JF7: 115.48225 | JG7: 118.37536 | JH7: 121.42494 | JI7: 117.44972 | JJ7: 118.26348 | JK7: 124.7352 | JL7: 134.14728 | JM7: 143.31024 | JN7: 140.84545 | JO7: 120.96604 | JP7: 103.41323 | JQ7: 110.18938 | JR7: 114.73487 | JS7: 117.60884 | JT7: 120.63825 | JU7: 116.68837 | JV7: 117.49644 | JW7: 123.92575 | JX7: 133.27628 | JY7: 142.37925 | JZ7: 139.92997 | KA7: 120.17935 | KB7: 102.74033 | KC7: 109.47199 | KD7: 113.98748 | KE7: 116.84232 | KF7: 119.85156 | KG7: 115.92702 | KH7: 116.7294 | KI7: 123.1163 | KJ7: 132.40528 | KK7: 141.44825 | KL7: 139.01449 | KM7: 119.39265 | KN7: 102.06742 | KO7: 108.7546 | KP7: 113.2401 | KQ7: 116.0758 | KR7: 119.06486 | KS7: 115.16567 | KT7: 115.96236 | KU7: 122.30685 | KV7: 131.53428 | KW7: 140.51725 | KX7: 138.099 | KY7: 118.60596 | KZ7: 101.39452 | LA7: 108.03722
N8: 270.42522 | O8: 277.46723 | P8: 284.4117 | Q8: 275.39006 | R8: 280.24405 | S8: 297.23265 | T8: 319.72843 | U8: 340.21153 | V8: 331.00318 | W8: 285.00267 | X8: 243.56471 | Y8: 261.06353 | Z8: 268.88447 | AA8: 275.8856 | AB8: 282.78972 | AC8: 273.81878 | AD8: 278.64432 | AE8: 295.53513 | AF8: 317.90157 | AG8: 338.2667 | AH8: 329.1101 | AI8: 283.3719 | AJ8: 242.17038 | AK8: 259.56831 | AL8: 267.34372 | AM8: 274.30398 | AN8: 281.16774 | AO8: 272.2475 | AP8: 277.04459 | AQ8: 293.83761 | AR8: 316.07471 | AS8: 336.32188 | AT8: 327.21701 | AU8: 281.74112 | AV8: 240.77604 | AW8: 258.07308 | AX8: 265.80297 | AY8: 272.72235 | AZ8: 279.54576 | BA8: 270.67623 | BB8: 275.44485 | BC8: 292.1401 | BD8: 314.24785 | BE8: 334.37706 | BF8: 325.32393 | BG8: 280.11035 | BH8: 239.38171 | BI8: 256.57786 | BJ8: 264.26222 | BK8: 271.14073 | BL8: 277.92378 | BM8: 269.10495 | BN8: 273.84512 | BO8: 290.44258 | BP8: 312.42098 | BQ8: 332.43223 | BR8: 323.43084 | BS8: 278.47957 | BT8: 237.98738 | BU8: 255.08264 | BV8: 262.72147 | BW8: 269.5591 | BX8: 276.3018 | BY8: 267.53367 | BZ8: 272.24539 | CA8: 288.74506 | CB8: 310.59412 | CC8: 330.48741 | CD8: 321.53776 | CE8: 276.8488 | CF8: 236.59304 | CG8: 253.58742 | CH8: 261.18071 | CI8: 267.97748 | CJ8: 274.67982 | CK8: 265.9624 | CL8: 270.64566 | CM8: 287.04754 | CN8: 308.76726 | CO8: 328.54259 | CP8: 319.64467 | CQ8: 275.21802 | CR8: 235.19871 | CS8: 252.09219 | CT8: 259.63996 | CU8: 266.39586 | CV8: 273.05784 | CW8: 264.39112 | CX8: 269.04592 | CY8: 285.35003 | CZ8: 306.9404 | DA8: 326.59776 | DB8: 317.75158 | DC8: 273.58725 | DD8: 233.80437 | DE8: 250.59697 | DF8: 258.09921 | DG8: 264.81423 | DH8: 271.43586 | DI8: 262.81984 | DJ8: 267.44619 | DK8: 283.65251 | DL8: 305.11354 | DM8: 324.65294 | DN8: 315.8585 | DO8: 271.95647 | DP8: 232.41004 | DQ8: 249.10175 | DR8: 256.55846 | DS8: 263.23261 | DT8: 269.81388 | DU8: 261.24857 | DV8: 265.84646 | DW8: 281.95499 | DX8: 303.28668 | DY8: 322.70812 | DZ8: 313.96541 | EA8: 270.3257 | EB8: 231.01571 | EC8: 247.60653 | ED8: 255.01771 | EE8: 261.65098 | EF8: 268.1919 | EG8: 259.67729 | EH8: 264.24673 | EI8: 280.25748 | EJ8: 301.45982 | EK8: 320.76329 | EL8: 312.07233 | EM8: 268.69492 | EN8: 229.62137 | EO8: 246.11131 | EP8: 253.47696 | EQ8: 260.06936 | ER8: 266.56992 | ES8: 258.10601 | ET8: 262.64699 | EU8: 278.55996 | EV8: 299.63295 | EW8: 318.81847 | EX8: 310.17924 | EY8: 267.06415 | EZ8: 228.22704 | FA8: 244.61608 | FB8: 251.93621 | FC8: 258.48773 | FD8: 264.94794 | FE8: 256.53473 | FF8: 261.04726 | FG8: 276.86244 | FH8: 297.80609 | FI8: 316.87364 | FJ8: 308.28616 | FK8: 265.43337 | FL8: 226.83271 | FM8: 243.12086 | FN8: 250.39545 | FO8: 256.90611 | FP8: 263.32596 | FQ8: 254.96346 | FR8: 259.44753 | FS8: 275.16493 | FT8: 295.97923 | FU8: 314.92882 | FV8: 306.39307 | FW8: 263.8026 | FX8: 225.43837 | FY8: 241.62564 | FZ8: 248.8547 | GA8: 255.32449 | GB8: 261.70398 | GC8: 253.39218 | GD8: 257.8478 | GE8: 273.46741 | GF8: 294.15237 | GG8: 312.984 | GH8: 304.49998 | GI8: 262.17182 | GJ8: 224.04404 | GK8: 240.13042 | GL8: 247.31395 | GM8: 253.74286 | GN8: 260.082 | GO8: 251.8209 | GP8: 256.24806 | GQ8: 271.76989 | GR8: 292.32551 | GS8: 311.03917 | GT8: 302.6069 | GU8: 260.54105 | GV8: 222.64971 | GW8: 238.6352 | GX8: 245.7732 | GY8: 252.16124 | GZ8: 258.46002 | HA8: 250.24963 | HB8: 254.64833 | HC8: 270.07238 | HD8: 290.49865 | HE8: 309.09435 | HF8: 300.71381 | HG8: 258.91027 | HH8: 221.25537 | HI8: 237.13997 | HJ8: 244.23245 | HK8: 250.57961 | HL8: 256.83804 | HM8: 248.67835 | HN8: 253.0486 | HO8: 268.37486 | HP8: 288.67179 | HQ8: 307.14953 | HR8: 298.82073 | HS8: 257.2795 | HT8: 219.86104 | HU8: 235.64475 | HV8: 242.6917 | HW8: 248.99799 | HX8: 255.21606 | HY8: 247.10707 | HZ8: 251.44887 | IA8: 266.67734 | IB8: 286.84492 | IC8: 305.2047 | ID8: 296.92764 | IE8: 255.64872 | IF8: 218.46671 | IG8: 234.14953 | IH8: 241.15095 | II8: 247.41636 | IJ8: 253.59408 | IK8: 245.5358 | IL8: 249.84913 | IM8: 264.97982 | IN8: 285.01806 | IO8: 303.25988 | IP8: 295.03455 | IQ8: 254.01795 | IR8: 217.07237 | IS8: 232.65431 | IT8: 239.61019 | IU8: 245.83474 | IV8: 251.9721 | IW8: 243.96452 | IX8: 248.2494 | IY8: 263.28231 | IZ8: 283.1912 | JA8: 301.31506 | JB8: 293.14147 | JC8: 252.38717 | JD8: 215.67804 | JE8: 231.15908 | JF8: 238.06944 | JG8: 244.25312 | JH8: 250.35012 | JI8: 242.39324 | JJ8: 246.64967 | JK8: 261.58479 | JL8: 281.36434 | JM8: 299.37023 | JN8: 291.24838 | JO8: 250.7564 | JP8: 214.28371 | JQ8: 229.66386 | JR8: 236.52869 | JS8: 242.67149 | JT8: 248.72814 | JU8: 240.82197 | JV8: 245.04994 | JW8: 259.88727 | JX8: 279.53748 | JY8: 297.42541 | JZ8: 289.3553 | KA8: 249.12562 | KB8: 212.88937 | KC8: 228.16864 | KD8: 234.98794 | KE8: 241.08987 | KF8: 247.10616 | KG8: 239.25069 | KH8: 243.4502 | KI8: 258.18976 | KJ8: 277.71062 | KK8: 295.48059 | KL8: 287.46221 | KM8: 247.49485 | KN8: 211.49504 | KO8: 226.67342 | KP8: 233.44719 | KQ8: 239.50824 | KR8: 245.48418 | KS8: 237.67941 | KT8: 241.85047 | KU8: 256.49224 | KV8: 275.88376 | KW8: 293.53576 | KX8: 285.56913 | KY8: 245.86407 | KZ8: 210.10071 | LA8: 225.1782
N9: 176.31299 | O9: 180.85734 | P9: 185.39729 | Q9: 179.41628 | R9: 181.14331 | S9: 191.29198 | T9: 205.7764 | U9: 219.704 | V9: 215.52933 | W9: 185.05173 | X9: 158.12707 | Y9: 168.79915 | Z9: 175.30844 | AA9: 179.82641 | AB9: 184.33998 | AC9: 178.39259 | AD9: 180.10928 | AE9: 190.1995 | AF9: 204.60063 | AG9: 218.44806 | AH9: 214.29667 | AI9: 183.99287 | AJ9: 157.22184 | AK9: 167.83236 | AL9: 174.3039 | AM9: 178.79548 | AN9: 183.28267 | AO9: 177.36891 | AP9: 179.07525 | AQ9: 189.10702 | AR9: 203.42487 | AS9: 217.19212 | AT9: 213.06401 | AU9: 182.93401 | AV9: 156.31661 | AW9: 166.86558 | AX9: 173.29935 | AY9: 177.76456 | AZ9: 182.22537 | BA9: 176.34522 | BB9: 178.04122 | BC9: 188.01454 | BD9: 202.24911 | BE9: 215.93618 | BF9: 211.83134 | BG9: 181.87515 | BH9: 155.41138 | BI9: 165.89879 | BJ9: 172.29481 | BK9: 176.73363 | BL9: 181.16806 | BM9: 175.32154 | BN9: 177.00719 | BO9: 186.92206 | BP9: 201.07334 | BQ9: 214.68024 | BR9: 210.59868 | BS9: 180.81629 | BT9: 154.50615 | BU9: 164.93201 | BV9: 171.29026 | BW9: 175.7027 | BX9: 180.11075 | BY9: 174.29785 | BZ9: 175.97316 | CA9: 185.82957 | CB9: 199.89758 | CC9: 213.4243 | CD9: 209.36602 | CE9: 179.75743 | CF9: 153.60092 | CG9: 163.96522 | CH9: 170.28572 | CI9: 174.67178 | CJ9: 179.05344 | CK9: 173.27417 | CL9: 174.93913 | CM9: 184.73709 | CN9: 198.72182 | CO9: 212.16836 | CP9: 208.13335 | CQ9: 178.69857 | CR9: 152.6957 | CS9: 162.99844 | CT9: 169.28117 | CU9: 173.64085 | CV9: 177.99614 | CW9: 172.25048 | CX9: 173.9051 | CY9: 183.64461 | CZ9: 197.54605 | DA9: 210.91241 | DB9: 206.90069 | DC9: 177.63971 | DD9: 151.79047 | DE9: 162.03165 | DF9: 168.27662 | DG9: 172.60992 | DH9: 176.93883 | DI9: 171.2268 | DJ9: 172.87107 | DK9: 182.55213 | DL9: 196.37029 | DM9: 209.65647 | DN9: 205.66803 | DO9: 176.58086 | DP9: 150.88524 | DQ9: 161.06487 | DR9: 167.27208 | DS9: 171.579 | DT9: 175.88152 | DU9: 170.20311 | DV9: 171.83704 | DW9: 181.45964 | DX9: 195.19453 | DY9: 208.40053 | DZ9: 204.43536 | EA9: 175.522 | EB9: 149.98001 | EC9: 160.09808 | ED9: 166.26753 | EE9: 170.54807 | EF9: 174.82421 | EG9: 169.17943 | EH9: 170.80301 | EI9: 180.36716 | EJ9: 194.01876 | EK9: 207.14459 | EL9: 203.2027 | EM9: 174.46314 | EN9: 149.07478 | EO9: 159.1313 | EP9: 165.26299 | EQ9: 169.51714 | ER9: 173.76691 | ES9: 168.15574 | ET9: 169.76897 | EU9: 179.27468 | EV9: 192.843 | EW9: 205.88865 | EX9: 201.97004 | EY9: 173.40428 | EZ9: 148.16955 | FA9: 158.16451 | FB9: 164.25844 | FC9: 168.48622 | FD9: 172.7096 | FE9: 167.13206 | FF9: 168.73494 | FG9: 178.1822 | FH9: 191.66724 | FI9: 204.63271 | FJ9: 200.73737 | FK9: 172.34542 | FL9: 147.26432 | FM9: 157.19773 | FN9: 163.2539 | FO9: 167.45529 | FP9: 171.65229 | FQ9: 166.10837 | FR9: 167.70091 | FS9: 177.08972 | FT9: 190.49147 | FU9: 203.37677 | FV9: 199.50471 | FW9: 171.28656 | FX9: 146.35909 | FY9: 156.23094 | FZ9: 162.24935 | GA9: 166.42436 | GB9: 170.59498 | GC9: 165.08469 | GD9: 166.66688 | GE9: 175.99723 | GF9: 189.31571 | GG9: 202.12083 | GH9: 198.27205 | GI9: 170.2277 | GJ9: 145.45386 | GK9: 155.26416 | GL9: 161.2448 | GM9: 165.39344 | GN9: 169.53768 | GO9: 164.061 | GP9: 165.63285 | GQ9: 174.90475 | GR9: 188.13995 | GS9: 200.86489 | GT9: 197.03938 | GU9: 169.16884 | GV9: 144.54863 | GW9: 154.29737 | GX9: 160.24026 | GY9: 164.36251 | GZ9: 168.48037 | HA9: 163.03732 | HB9: 164.59882 | HC9: 173.81227 | HD9: 186.96418 | HE9: 199.60895 | HF9: 195.80672 | HG9: 168.10998 | HH9: 143.6434 | HI9: 153.33059 | HJ9: 159.23571 | HK9: 163.33158 | HL9: 167.42306 | HM9: 162.01363 | HN9: 163.56479 | HO9: 172.71979 | HP9: 185.78842 | HQ9: 198.35301 | HR9: 194.57406 | HS9: 167.05112 | HT9: 142.73817 | HU9: 152.36381 | HV9: 158.23117 | HW9: 162.30066 | HX9: 166.36575 | HY9: 160.98995 | HZ9: 162.53076 | IA9: 171.6273 | IB9: 184.61266 | IC9: 197.09707 | ID9: 193.34139 | IE9: 165.99226 | IF9: 141.83295 | IG9: 151.39702 | IH9: 157.22662 | II9: 161.26973 | IJ9: 165.30844 | IK9: 159.96626 | IL9: 161.49673 | IM9: 170.53482 | IN9: 183.43689 | IO9: 195.84113 | IP9: 192.10873 | IQ9: 164.9334 | IR9: 140.92772 | IS9: 150.43024 | IT9: 156.22208 | IU9: 160.2388 | IV9: 164.25114 | IW9: 158.94258 | IX9: 160.4627 | IY9: 169.44234 | IZ9: 182.26113 | JA9: 194.58518 | JB9: 190.87607 | JC9: 163.87454 | JD9: 140.02249 | JE9: 149.46345 | JF9: 155.21753 | JG9: 159.20788 | JH9: 163.19383 | JI9: 157.91889 | JJ9: 159.42867 | JK9: 168.34986 | JL9: 181.08537 | JM9: 193.32924 | JN9: 189.6434 | JO9: 162.81568 | JP9: 139.11726 | JQ9: 148.49667 | JR9: 154.21298 | JS9: 158.17695 | JT9: 162.13652 | JU9: 156.89521 | JV9: 158.39464 | JW9: 167.25738 | JX9: 179.9096 | JY9: 192.0733 | JZ9: 188.41074 | KA9: 161.75682 | KB9: 138.21203 | KC9: 147.52988 | KD9: 153.20844 | KE9: 157.14602 | KF9: 161.07921 | KG9: 155.87152 | KH9: 157.36061 | KI9: 166.16489 | KJ9: 178.73384 | KK9: 190.81736 | KL9: 187.17807 | KM9: 160.69796 | KN9: 137.3068 | KO9: 146.5631 | KP9: 152.20389 | KQ9: 156.1151 | KR9: 160.02191 | KS9: 154.84784 | KT9: 156.32658 | KU9: 165.07241 | KV9: 177.55808 | KW9: 189.56142 | KX9: 185.94541 | KY9: 159.6391 | KZ9: 136.40157 | LA9: 145.59631
N10: 176.31299 | O10: 180.85734 | P10: 185.39729 | Q10: 179.41628 | R10: 181.14331 | S10: 191.29198 | T10: 205.7764 | U10: 219.704 | V10: 215.52933 | W10: 185.05173 | X10: 158.12707 | Y10: 168.79915 | Z10: 175.30844 | AA10: 179.82641 | AB10: 184.33998 | AC10: 178.39259 | AD10: 180.10928 | AE10: 190.1995 | AF10: 204.60063 | AG10: 218.44806 | AH10: 214.29667 | AI10: 183.99287 | AJ10: 157.22184 | AK10: 167.83236 | AL10: 174.3039 | AM10: 178.79548 | AN10: 183.28267 | AO10: 177.36891 | AP10: 179.07525 | AQ10: 189.10702 | AR10: 203.42487 | AS10: 217.19212 | AT10: 213.06401 | AU10: 182.93401 | AV10: 156.31661 | AW10: 166.86558 | AX10: 173.29935 | AY10: 177.76456 | AZ10: 182.22537 | BA10: 176.34522 | BB10: 178.04122 | BC10: 188.01454 | BD10: 202.24911 | BE10: 215.93618 | BF10: 211.83134 | BG10: 181.87515 | BH10: 155.41138 | BI10: 165.89879 | BJ10: 172.29481 | BK10: 176.73363 | BL10: 181.16806 | BM10: 175.32154 | BN10: 177.00719 | BO10: 186.92206 | BP10: 201.07334 | BQ10: 214.68024 | BR10: 210.59868 | BS10: 180.81629 | BT10: 154.50615 | BU10: 164.93201 | BV10: 171.29026 | BW10: 175.7027 | BX10: 180.11075 | BY10: 174.29785 | BZ10: 175.97316 | CA10: 185.82957 | CB10: 199.89758 | CC10: 213.4243 | CD10: 209.36602 | CE10: 179.75743 | CF10: 153.60092 | CG10: 163.96522 | CH10: 170.28572 | CI10: 174.67178 | CJ10: 179.05344 | CK10: 173.27417 | CL10: 174.93913 | CM10: 184.73709 | CN10: 198.72182 | CO10: 212.16836 | CP10: 208.13335 | CQ10: 178.69857 | CR10: 152.6957 | CS10: 162.99844 | CT10: 169.28117 | CU10: 173.64085 | CV10: 177.99614 | CW10: 172.25048 | CX10: 173.9051 | CY10: 183.64461 | CZ10: 197.54605 | DA10: 210.91241 | DB10: 206.90069 | DC10: 177.63971 | DD10: 151.79047 | DE10: 162.03165 | DF10: 168.27662 | DG10: 172.60992 | DH10: 176.93883 | DI10: 171.2268 | DJ10: 172.87107 | DK10: 182.55213 | DL10: 196.37029 | DM10: 209.65647 | DN10: 205.66803 | DO10: 176.58086 | DP10: 150.88524 | DQ10: 161.06487 | DR10: 167.27208 | DS10: 171.579 | DT10: 175.88152 | DU10: 170.20311 | DV10: 171.83704 | DW10: 181.45964 | DX10: 195.19453 | DY10: 208.40053 | DZ10: 204.43536 | EA10: 175.522 | EB10: 149.98001 | EC10: 160.09808 | ED10: 166.26753 | EE10: 170.54807 | EF10: 174.82421 | EG10: 169.17943 | EH10: 170.80301 | EI10: 180.36716 | EJ10: 194.01876 | EK10: 207.14459 | EL10: 203.2027 | EM10: 174.46314 | EN10: 149.07478 | EO10: 159.1313 | EP10: 165.26299 | EQ10: 169.51714 | ER10: 173.76691 | ES10: 168.15574 | ET10: 169.76897 | EU10: 179.27468 | EV10: 192.843 | EW10: 205.88865 | EX10: 201.97004 | EY10: 173.40428 | EZ10: 148.16955 | FA10: 158.16451 | FB10: 164.25844 | FC10: 168.48622 | FD10: 172.7096 | FE10: 167.13206 | FF10: 168.73494 | FG10: 178.1822 | FH10: 191.66724 | FI10: 204.63271 | FJ10: 200.73737 | FK10: 172.34542 | FL10: 147.26432 | FM10: 157.19773 | FN10: 163.2539 | FO10: 167.45529 | FP10: 171.65229 | FQ10: 166.10837 | FR10: 167.70091 | FS10: 177.08972 | FT10: 190.49147 | FU10: 203.37677 | FV10: 199.50471 | FW10: 171.28656 | FX10: 146.35909 | FY10: 156.23094 | FZ10: 162.24935 | GA10: 166.42436 | GB10: 170.59498 | GC10: 165.08469 | GD10: 166.66688 | GE10: 175.99723 | GF10: 189.31571 | GG10: 202.12083 | GH10: 198.27205 | GI10: 170.2277 | GJ10: 145.45386 | GK10: 155.26416 | GL10: 161.2448 | GM10: 165.39344 | GN10: 169.53768 | GO10: 164.061 | GP10: 165.63285 | GQ10: 174.90475 | GR10: 188.13995 | GS10: 200.86489 | GT10: 197.03938 | GU10: 169.16884 | GV10: 144.54863 | GW10: 154.29737 | GX10: 160.24026 | GY10: 164.36251 | GZ10: 168.48037 | HA10: 163.03732 | HB10: 164.59882 | HC10: 173.81227 | HD10: 186.96418 | HE10: 199.60895 | HF10: 195.80672 | HG10: 168.10998 | HH10: 143.6434 | HI10: 153.33059 | HJ10: 159.23571 | HK10: 163.33158 | HL10: 167.42306 | HM10: 162.01363 | HN10: 163.56479 | HO10: 172.71979 | HP10: 185.78842 | HQ10: 198.35301 | HR10: 194.57406 | HS10: 167.05112 | HT10: 142.73817 | HU10: 152.36381 | HV10: 158.23117 | HW10: 162.30066 | HX10: 166.36575 | HY10: 160.98995 | HZ10: 162.53076 | IA10: 171.6273 | IB10: 184.61266 | IC10: 197.09707 | ID10: 193.34139 | IE10: 165.99226 | IF10: 141.83295 | IG10: 151.39702 | IH10: 157.22662 | II10: 161.26973 | IJ10: 165.30844 | IK10: 159.96626 | IL10: 161.49673 | IM10: 170.53482 | IN10: 183.43689 | IO10: 195.84113 | IP10: 192.10873 | IQ10: 164.9334 | IR10: 140.92772 | IS10: 150.43024 | IT10: 156.22208 | IU10: 160.2388 | IV10: 164.25114 | IW10: 158.94258 | IX10: 160.4627 | IY10: 169.44234 | IZ10: 182.26113 | JA10: 194.58518 | JB10: 190.87607 | JC10: 163.87454 | JD10: 140.02249 | JE10: 149.46345 | JF10: 155.21753 | JG10: 159.20788 | JH10: 163.19383 | JI10: 157.91889 | JJ10: 159.42867 | JK10: 168.34986 | JL10: 181.08537 | JM10: 193.32924 | JN10: 189.6434 | JO10: 162.81568 | JP10: 139.11726 | JQ10: 148.49667 | JR10: 154.21298 | JS10: 158.17695 | JT10: 162.13652 | JU10: 156.89521 | JV10: 158.39464 | JW10: 167.25738 | JX10: 179.9096 | JY10: 192.0733 | JZ10: 188.41074 | KA10: 161.75682 | KB10: 138.21203 | KC10: 147.52988 | KD10: 153.20844 | KE10: 157.14602 | KF10: 161.07921 | KG10: 155.87152 | KH10: 157.36061 | KI10: 166.16489 | KJ10: 178.73384 | KK10: 190.81736 | KL10: 187.17807 | KM10: 160.69796 | KN10: 137.3068 | KO10: 146.5631 | KP10: 152.20389 | KQ10: 156.1151 | KR10: 160.02191 | KS10: 154.84784 | KT10: 156.32658 | KU10: 165.07241 | KV10: 177.55808 | KW10: 189.56142 | KX10: 185.94541 | KY10: 159.6391 | KZ10: 136.40157 | LA10: 145.59631
N11: 622.36814 | O11: 658.96633 | P11: 544.22591 | Q11: 523.93899 | R11: 440.9713 | S11: 468.03934 | T11: 415.26815 | U11: 434.89897 | V11: 597.09192 | W11: 491.87325 | X11: 681.40852 | Y11: 611.91522 | Z11: 619.8218 | AA11: 656.26934 | AB11: 541.99776 | AC11: 521.79316 | AD11: 439.16466 | AE11: 466.12115 | AF11: 413.56565 | AG11: 433.11538 | AH11: 594.64231 | AI11: 489.85462 | AJ11: 678.61108 | AK11: 609.40222 | AL11: 617.27546 | AM11: 653.57234 | AN11: 539.76961 | AO11: 519.64734 | AP11: 437.35801 | AQ11: 464.20296 | AR11: 411.86315 | AS11: 431.33179 | AT11: 592.1927 | AU11: 487.83598 | AV11: 675.81365 | AW11: 606.88922 | AX11: 614.72912 | AY11: 650.87534 | AZ11: 537.54146 | BA11: 517.50151 | BB11: 435.55137 | BC11: 462.28476 | BD11: 410.16065 | BE11: 429.5482 | BF11: 589.74309 | BG11: 485.81735 | BH11: 673.01621 | BI11: 604.37622 | BJ11: 612.18277 | BK11: 648.17834 | BL11: 535.31331 | BM11: 515.35569 | BN11: 433.74473 | BO11: 460.36657 | BP11: 408.45815 | BQ11: 427.76461 | BR11: 587.29349 | BS11: 483.79872 | BT11: 670.21878 | BU11: 601.86322 | BV11: 609.63643 | BW11: 645.48135 | BX11: 533.08516 | BY11: 513.20986 | BZ11: 431.93809 | CA11: 458.44837 | CB11: 406.75565 | CC11: 425.98102 | CD11: 584.84388 | CE11: 481.78009 | CF11: 667.42134 | CG11: 599.35022 | CH11: 607.09009 | CI11: 642.78435 | CJ11: 530.85701 | CK11: 511.06404 | CL11: 430.13145 | CM11: 456.53018 | CN11: 405.05315 | CO11: 424.19743 | CP11: 582.39427 | CQ11: 479.76146 | CR11: 664.62391 | CS11: 596.83722 | CT11: 604.54375 | CU11: 640.08735 | CV11: 528.62886 | CW11: 508.91821 | CX11: 428.3248 | CY11: 454.61198 | CZ11: 403.35065 | DA11: 422.41384 | DB11: 579.94466 | DC11: 477.74283 | DD11: 661.82647 | DE11: 594.32422 | DF11: 601.99741 | DG11: 637.39035 | DH11: 526.40071 | DI11: 506.77239 | DJ11: 426.51816 | DK11: 452.69379 | DL11: 401.64815 | DM11: 420.63024 | DN11: 577.49506 | DO11: 475.72419 | DP11: 659.02904 | DQ11: 591.81122 | DR11: 599.45107 | DS11: 634.69336 | DT11: 524.17255 | DU11: 504.62656 | DV11: 424.71152 | DW11: 450.7756 | DX11: 399.94565 | DY11: 418.84665 | DZ11: 575.04545 | EA11: 473.70556 | EB11: 656.2316 | EC11: 589.29823 | ED11: 596.90473 | EE11: 631.99636 | EF11: 521.9444 | EG11: 502.48074 | EH11: 422.90488 | EI11: 448.8574 | EJ11: 398.24315 | EK11: 417.06306 | EL11: 572.59584 | EM11: 471.68693 | EN11: 653.43417 | EO11: 586.78523 | EP11: 594.35839 | EQ11: 629.29936 | ER11: 519.71625 | ES11: 500.33491 | ET11: 421.09823 | EU11: 446.93921 | EV11: 396.54065 | EW11: 415.27947 | EX11: 570.14623 | EY11: 469.6683 | EZ11: 650.63673 | FA11: 584.27223 | FB11: 591.81205 | FC11: 626.60237 | FD11: 517.4881 | FE11: 498.18909 | FF11: 419.29159 | FG11: 445.02101 | FH11: 394.83815 | FI11: 413.49588 | FJ11: 567.69662 | FK11: 467.64967 | FL11: 647.8393 | FM11: 581.75923 | FN11: 589.26571 | FO11: 623.90537 | FP11: 515.25995 | FQ11: 496.04326 | FR11: 417.48495 | FS11: 443.10282 | FT11: 393.13565 | FU11: 411.71229 | FV11: 565.24702 | FW11: 465.63104 | FX11: 645.04186 | FY11: 579.24623 | FZ11: 586.71937 | GA11: 621.20837 | GB11: 513.0318 | GC11: 493.89744 | GD11: 415.67831 | GE11: 441.18463 | GF11: 391.43315 | GG11: 409.9287 | GH11: 562.79741 | GI11: 463.6124 | GJ11: 642.24443 | GK11: 576.73323 | GL11: 584.17303 | GM11: 618.51137 | GN11: 510.80365 | GO11: 491.75161 | GP11: 413.87166 | GQ11: 439.26643 | GR11: 389.73065 | GS11: 408.14511 | GT11: 560.3478 | GU11: 461.59377 | GV11: 639.44699 | GW11: 574.22023 | GX11: 581.62668 | GY11: 615.81438 | GZ11: 508.5755 | HA11: 489.60579 | HB11: 412.06502 | HC11: 437.34824 | HD11: 388.02815 | HE11: 406.36152 | HF11: 557.89819 | HG11: 459.57514 | HH11: 636.64956 | HI11: 571.70723 | HJ11: 579.08034 | HK11: 613.11738 | HL11: 506.34734 | HM11: 487.45996 | HN11: 410.25838 | HO11: 435.43004 | HP11: 386.32565 | HQ11: 404.57792 | HR11: 555.44858 | HS11: 457.55651 | HT11: 633.85212 | HU11: 569.19424 | HV11: 576.534 | HW11: 610.42038 | HX11: 504.11919 | HY11: 485.31413 | HZ11: 408.45174 | IA11: 433.51185 | IB11: 384.62315 | IC11: 402.79433 | ID11: 552.99898 | IE11: 455.53788 | IF11: 631.05469 | IG11: 566.68124 | IH11: 573.98766 | II11: 607.72338 | IJ11: 501.89104 | IK11: 483.16831 | IL11: 406.64509 | IM11: 431.59366 | IN11: 382.92065 | IO11: 401.01074 | IP11: 550.54937 | IQ11: 453.51925 | IR11: 628.25725 | IS11: 564.16824 | IT11: 571.44132 | IU11: 605.02639 | IV11: 499.66289 | IW11: 481.02248 | IX11: 404.83845 | IY11: 429.67546 | IZ11: 381.21815 | JA11: 399.22715 | JB11: 548.09976 | JC11: 451.50061 | JD11: 625.45982 | JE11: 561.65524 | JF11: 568.89498 | JG11: 602.32939 | JH11: 497.43474 | JI11: 478.87666 | JJ11: 403.03181 | JK11: 427.75727 | JL11: 379.51565 | JM11: 397.44356 | JN11: 545.65015 | JO11: 449.48198 | JP11: 622.66238 | JQ11: 559.14224 | JR11: 566.34864 | JS11: 599.63239 | JT11: 495.20659 | JU11: 476.73083 | JV11: 401.22517 | JW11: 425.83907 | JX11: 377.81315 | JY11: 395.65997 | JZ11: 543.20054 | KA11: 447.46335 | KB11: 619.86495 | KC11: 556.62924 | KD11: 563.8023 | KE11: 596.9354 | KF11: 492.97844 | KG11: 474.58501 | KH11: 399.41852 | KI11: 423.92088 | KJ11: 376.11065 | KK11: 393.87638 | KL11: 540.75094 | KM11: 445.44472 | KN11: 617.06751 | KO11: 554.11624 | KP11: 561.25596 | KQ11: 594.2384 | KR11: 490.75029 | KS11: 472.43918 | KT11: 397.61188 | KU11: 422.00269 | KV11: 374.40815 | KW11: 392.09279 | KX11: 538.30133 | KY11: 443.42609 | KZ11: 614.27008 | LA11: 551.60324
